Workbook

Sheet DATOS
B3: ACTIVIDAD DE REFUERZO ESCENARIO SEIS
B4: ELABORACION DE ESTADOS FINANCIEROS
C13: Año 1 | D13: Año 2 | E13: Año 3
B14: Caja y Bancos | C14: 245 | D14: 440 | E14: 260
B15: Impuesto de renta por pagar | C15: 232.9 | D15: 491.8134 | E15: 522.1062
B16: Intereses(Gastos financieros) | C16: 270 | D16: 443.49 | E16: 877.86
B17: Obligaciones financieras largo plazo | C17: 350 | D17: 1500 | E17: 1250
B18: Terrenos | C18: 400 | D18: 400 | E18: 500
B19: Depreciación Acumulada | C19: 455 | D19: 675 | E19: 1045
B20: Utilidades retenidas | C20: 384 | D20: 260 | E20: 1028
B21: Inventarios | C21: 1345 | D21: 1985 | E21: 3230
B22: Obligaciones financieras Corto Plazo | C22: 1476 | D22: 1668 | E22: 4711
B23: Maquinaria y Equipo | C23: 1555 | D23: 1625 | E23: 3605
B24: Proveedores | C24: 1905 | D24: 2205 | E24: 4009
B25: Gastos de Administración | C25: 2090 | D25: 2555 | E25: 3275
... B31: Ventas netas (100% a crédito) | C31: 16980 | D31: 21980 | E31: 30250

Sheet ESTADO DE RESULTADOS
C6: EMPRESA MANUFACTURERA S.A.
C7: ESTADO DE RESULTADOS
C8: Del 1 al 31 de Diciembre
C9: (Cifras en millones de pesos)
D12: AÑO 1 | E12: AÑO 2 | F12: AÑO 3
C13: Ventas netas (100% a crédito) | D13: =+DATOS!C31 -> 16980 | E13: =+DATOS!D31 -> 21980 | F13: =+DATOS!E31 -> 30250
C14: Menos : Costo de Productos vendidos | D14: =+DATOS!C30 -> 10685 | E14: =+DATOS!D30 -> 13445 | F14: =+DATOS!E30 -> 19610
C15: = UTILIDAD BRUTA EN VENTAS | D15: =+D13-D14 -> 6295 | E15: =+E13-E14 -> 8535 | F15: =+F13-F14 -> 10640
C16: Menos: Gastos de Administración | D16: =+DATOS!C25 -> 2090 | E16: =+DATOS!D25 -> 2555 | F16: =+DATOS!E25 -> 3275
C17: Gastos de Ventas | D17: =+DATOS!C27 -> 3250 | E17: =+DATOS!D27 -> 4090 | F17: =+DATOS!E27 -> 4905
C18: = UTILIDAD OPERACIONAL (U.A.I.I.) | D18: =+D15-D16-D17 -> 955 | E18: =+E15-E16-E17 -> 1890 | F18: =+F15-F16-F17 -> 2460
C19: Menos Intereses(Gastos financieros) | D19: =+DATOS!C16 -> 270 | E19: =+DATOS!D16 -> 443.49 | F19: =+DATOS!E16 -> 877.86
C20: = UTILIDAD ANTES DE IMPUESTOS (UAI) | D20: =+D18-D19 -> 685 | E20: =+E18-E19 -> 1446.51 | F20: =+F18-F19 -> 1582.14
C21: Menos Impuestos | D21: =+DATOS!C15 -> 232.9 | E21: =+DATOS!D15 -> 491.8134 | F21: =+DATOS!E15 -> 522.1062
C22: = UTILIDAD NETA | D22: =+D20-D21 -> 452.1 | E22: =+E20-E21 -> 954.6966 | F22: =+F20-F21 -> 1060.0338
C24: Tasa de impuesto a la renta | D24: =+D21/D20 -> 0.34 | E24: =+E21/E20 -> 0.34 | F24: =+F21/F20 -> 0.33

Sheet ESTADO DE SITUACION FINANCIERA
C3: EMPRESA MANUFACTURERA S.A.
C4: ESTADO DE SITUACION FINANCIERA
C5: A 31 de Diciembre
C9: (Cifras en millones de pesos) | D9: AÑO 1 | E9: AÑO 2 | F9: AÑO 3
C10: ACTIVOS
C11: Caja y Bancos (Efectivo) | D11: =+DATOS!C14 -> 245 | E11: =+DATOS!D14 -> 440 | F11: =+DATOS!E14 -> 260
C12: Cuentas por cobrar | D12: =DATOS!$C$28 -> 4075 | E12: =DATOS!D28 -> 5865 | F12: =DATOS!E28 -> 8390
C13: Inventarios | D13: =DATOS!$C$21 -> 1345 | E13: =DATOS!D21 -> 1985 | F13: =DATOS!E21 -> 3230
C14: Total Activos Corrientes | D14: =SUM(D11:D13) -> 5665 | E14: =SUM(E11:E13) -> 8290 | F14: =SUM(F11:F13) -> 11880
C16: Terrenos | D16: =DATOS!C18 -> 400 | E16: =DATOS!D18 -> 400 | F16: =DATOS!E18 -> 500
C17: Edificios | D17: =DATOS!C26 -> 2295 | E17: =DATOS!D26 -> 2550 | F17: =DATOS!E26 -> 3750
C18: Maquinaria y Equipo | D18: =DATOS!C23 -> 1555 | E18: =DATOS!D23 -> 1625 | F18: =DATOS!E23 -> 3605
C19: Depreciación Acumulada | D19: =-DATOS!C19 -> -455 | E19: =-DATOS!D19 -> -675 | F19: =-DATOS!E19 -> -1045
C20: Total Activos Fijos | D20: =SUM(D16:D19) -> 3795 | E20: =SUM(E16:E19) -> 3900 | F20: =SUM(F16:F19) -> 6810
C21: TOTAL ACTIVOS | D21: =D14+D20 -> 9460 | E21: =E14+E20 -> 12190 | F21: =F14+F20 -> 18690
C23: PASIVOS
C24: Obligaciones financieras Corto Plazo | D24: =DATOS!C22 -> 1476 | E24: =DATOS!D22 -> 1668 | F24: =DATOS!E22 -> 4711
C25: Impuestos por pagar | D25: =DATOS!C15 -> 232.9 | E25: =DATOS!D15 -> 491.8134 | F25: =DATOS!E15 -> 522.1062
C26: Proveedores | D26: =DATOS!C24 -> 1905 | E26: =DATOS!D24 -> 2205 | F26: =DATOS!E24 -> 4009
C27: Total Pasivo Corriente o Corto Plazo | D27: =SUM(D24:D26) -> 3613.9 | E27: =SUM(E24:E26) -> 4364.8134 | F27: =SUM(F24:F26) -> 9242.1062
C28: Obligaciones financieras largo plazo | D28: =DATOS!C17 -> 350 | E28: =DATOS!D17 -> 1500 | F28: =DATOS!E17 -> 1250
C29: TOTAL PASIVO | D29: =SUM(D27:D28) -> 3963.9 | E29: =SUM(E27:E28) -> 5864.8134 | F29: =SUM(F27:F28) -> 10492.106
C31: PATRIMONIO
C32: Capital | D32: =DATOS!C29 -> 4660 | E32: =DATOS!D29 -> 5110 | F32: =DATOS!E29 -> 6110
C33: Utilidad del ejercicio | D33: ='ESTADO DE RESULTADOS'!D22 -> 452.1 | E33: ='ESTADO DE RESULTADOS'!E22 -> 954.6966 | F33: ='ESTADO DE RESULTADOS'!F22 -> 1060.0338
C34: Utilidades retenidas | D34: =DATOS!C20 -> 384 | E34: =DATOS!D20 -> 260 | F34: =DATOS!E20 -> 1028
C35: Total Patrimonio | D35: =SUM(D32:D34) -> 5496.1 | E35: =SUM(E32:E34) -> 6324.6966 | F35: =SUM(F32:F34) -> 8198.0338
C36: TOTAL PASIVO Y PATRIMONIO | D36: =SUM(D35+D29) -> 9460 | E36: =SUM(E35+E29) -> 12189.51 | F36: =SUM(F35+F29) -> 18690.14
C37: CHEQUEO | D37: =+D36-D21 -> 0 | E37: =+E36-E21 -> -0.49 | F37: =+F36-F21 -> 0.14

Sheet A V Y H DE ESTADO DE RESULTADOS
B2: EMPRESA MANUFACTURERA S.A.
B3: ESTADO DE RESULTADOS
B4: Del 1 al 31 de Diciembre
B5: (Cifras en millones de pesos)
G6: LECTURA VERTICAL | K6: LECTURA HORIZONTAL
K7: Año 2 con 1 | M7: Año 3 con 2
C8: Año 1 | D8: Año 2 | E8: Año 3 | G8: Año 1 | H8: Año 2 | I8: Año 3 | K8: PESOS | L8: PORCENTAJE | M8: PESOS | N8: PORCENTAJE
B9: Ventas netas (100% a crédito) | C9: =DATOS!C31 -> 16980 | D9: =DATOS!D31 -> 21980 | E9: =DATOS!E31 -> 30250 | G9: 1 | H9: 1 | I9: 1 | K9: =D9-C9 -> 5000 | L9: =+K9/C9 -> 0.29446408 | M9: =E9-D9 -> 8270 | N9: =+M9/D9 -> 0.37625114
B10: Menos : Costo de Productos vendidos | C10: =DATOS!C30 -> 10685 | D10: =DATOS!D30 -> 13445 | E10: =DATOS!E30 -> 19610 | G10: =+C10/$C$9 -> 0.62926973 | H10: =+D10/$D$9 -> 0.61169245 | I10: =+E10/$E$9 -> 0.64826446 | K10: =D10-C10 -> 2760 | L10: =+K10/C10 -> 0.25830604 | M10: =E10-D10 -> 6165 | N10: =+M10/D10 -> 0.45853477
B11: UTILIDAD BRUTA EN VENTAS | C11: =C9-C10 -> 6295 | D11: =D9-D10 -> 8535 | E11: =E9-E10 -> 10640 | G11: 2 | H11: =+D11/$D$9 -> 0.38830755 | I11: =+E11/$E$9 -> 0.35173554 | K11: =D11-C11 -> 2240 | L11: =+K11/C11 -> 0.35583797 | M11: =E11-D11 -> 2105 | N11: =+M11/D11 -> 0.24663152
B12: Menos: Gastos de Administración | C12: ='ESTADO DE RESULTADOS'!D16 -> 2090 | D12: ='ESTADO DE RESULTADOS'!E16 -> 2555 | E12: ='ESTADO DE RESULTADOS'!F16 -> 3275 | G12: =+C12/$C$9 -> 0.12308598 | H12: =+D12/$D$9 -> 0.11624204 | I12: =+E12/$E$9 -> 0.10826446 | K12: =D12-C12 -> 465 | L12: =+K12/C12 -> 0.22248804 | M12: =E12-D12 -> 720 | N12: =+M12/D12 -> 0.28180039
B13: Gastos de Ventas | C13: ='ESTADO DE RESULTADOS'!D17 -> 3250 | D13: ='ESTADO DE RESULTADOS'!E17 -> 4090 | E13: ='ESTADO DE RESULTADOS'!F17 -> 4905 | G13: 3 | H13: =+D13/$D$9 -> 0.18607825 | I13: =+E13/$E$9 -> 0.16214876 | K13: =D13-C13 -> 840 | L13: =+K13/C13 -> 0.25846154 | M13: =E13-D13 -> 815 | N13: =+M13/D13 -> 0.1992665
B14: UTILIDAD OPERACIONAL (U.A.I.I.) | C14: =C11-C12-C13 -> 955 | D14: =D11-D12-D13 -> 1890 | E14: =E11-E12-E13 -> 2460 | G14: =+C14/$C$9 -> 0.056242638 | H14: =+D14/$D$9 -> 0.085987261 | I14: =+E14/$E$9 -> 0.081322314 | K14: =D14-C14 -> 935 | L14: =+K14/C14 -> 0.97905759 | M14: =E14-D14 -> 570 | N14: =+M14/D14 -> 0.3015873
B15: Menos Intereses(Gastos financieros) | C15: ='ESTADO DE RESULTADOS'!D19 -> 270 | D15: ='ESTADO DE RESULTADOS'!E19 -> 443.49 | E15: ='ESTADO DE RESULTADOS'!F19 -> 877.86 | G15: 4 | H15: =+D15/$D$9 -> 0.020176979 | I15: =+E15/$E$9 -> 0.029020165 | K15: =D15-C15 -> 173.49 | L15: =+K15/C15 -> 0.64255556 | M15: =E15-D15 -> 434.37 | N15: =+M15/D15 -> 0.97943584
B16: = UTILIDAD ANTES DE IMPUESTOS (UAI) | C16: =C14-C15 -> 685 | D16: =D14-D15 -> 1446.51 | E16: =E14-E15 -> 1582.14 | G16: =+C16/$C$9 -> 0.040341578 | H16: =+D16/$D$9 -> 0.065810282 | I16: =+E16/$E$9 -> 0.052302149 | K16: =D16-C16 -> 761.51 | L16: =+K16/C16 -> 1.1116934 | M16: =E16-D16 -> 135.63 | N16: =+M16/D16 -> 0.09376361
B17: Menos Impuestos | C17: ='ESTADO DE RESULTADOS'!D21 -> 232.9 | D17: ='ESTADO DE RESULTADOS'!E21 -> 491.8134 | E17: ='ESTADO DE RESULTADOS'!F21 -> 522.1062 | G17: 5 | H17: =+D17/$D$9 -> 0.022375496 | I17: =+E17/$E$9 -> 0.017259709 | K17: =D17-C17 -> 258.9134 | L17: =+K17/C17 -> 1.1116934 | M17: =E17-D17 -> 30.2928 | N17: =+M17/D17 -> 0.061594092
B18: = UTILIDAD NETA | C18: =C16-C17 -> 452.1 | D18: =D16-D17 -> 954.6966 | E18: =E16-E17 -> 1060.0338 | G18: =+C18/$C$9 -> 0.026625442 | H18: =+D18/$D$9 -> 0.043434786 | I18: =+E18/$E$9 -> 0.03504244 | K18: =D18-C18 -> 502.5966 | L18: =+K18/C18 -> 1.1116934 | M18: =E18-D18 -> 105.3372 | N18: =+M18/D18 -> 0.11033579

Sheet A V Y H DEL EST. SITUA FRA.
B1: EMPRESA MANUFACTURERA S.A.
B2: ESTADO DE SITUACION FINANCIERA
B3: A 31 de Diciembre
G5: LECTURA VERTICAL | K5: LECTURA HORIZONTAL
K6: Año 2 con 1 | M6: Año 3 con 2
B7: (Cifras en millones de pesos) | C7: Año 1 | D7: Año 2 | E7: Año 3 | G7: Año 1 | H7: Año 2 | I7: Año 3 | K7: PESOS | L7: PORCENTAJE | M7: PESOS | N7: PORCENTAJE
B8: ACTIVOS
B9: Caja y Bancos (Efectivo) | C9: ='ESTADO DE SITUACION FINANCIERA'!D11 -> 245 | D9: ='ESTADO DE SITUACION FINANCIERA'!E11 -> 440 | E9: ='ESTADO DE SITUACION FINANCIERA'!F11 -> 260 | G9: =+C9/$C$19 -> 0.02589852 | H9: =+D9/$D$19 -> 0.03609516 | I9: =+E9/$E$19 -> 0.013911182 | K9: =+D9-C9 -> 195 | L9: =+K9/C9 -> 0.79591837 | M9: =+E9-D9 -> -180 | N9: =+M9/D9 -> -0.40909091
B10: Cuentas por cobrar | C10: =+'ESTADO DE SITUACION FINANCIERA'!D12 -> 4075 | D10: =+'ESTADO DE SITUACION FINANCIERA'!E12 -> 5865 | E10: =+'ESTADO DE SITUACION FINANCIERA'!F12 -> 8390 | G10: =+C10/$C$19 -> 0.4307611 | H10: =+D10/$D$19 -> 0.48113208 | I10: =+E10/$E$19 -> 0.44890316 | K10: =+D10-C10 -> 1790 | L10: =+K10/C10 -> 0.4392638 | M10: =+E10-D10 -> 2525 | N10: =+M10/D10 -> 0.43052003
B11: Inventarios | C11: =+'ESTADO DE SITUACION FINANCIERA'!D13 -> 1345 | D11: =+'ESTADO DE SITUACION FINANCIERA'!E13 -> 1985 | E11: =+'ESTADO DE SITUACION FINANCIERA'!F13 -> 3230 | G11: =+C11/$C$19 -> 0.14217759 | H11: =+D11/$D$19 -> 0.16283839 | I11: =+E11/$E$19 -> 0.17281969 | K11: =+D11-C11 -> 640 | L11: =+K11/C11 -> 0.47583643 | M11: =+E11-D11 -> 1245 | N11: =+M11/D11 -> 0.62720403
B12: Total Activos Corrientes | C12: =SUM(C9:C11) -> 5665 | D12: =SUM(D9:D11) -> 8290 | E12: =SUM(E9:E11) -> 11880 | G12: =+C12/$C$19 -> 0.59883721 | H12: =+D12/$D$19 -> 0.68006563 | I12: =+E12/$E$19 -> 0.63563403 | K12: =+D12-C12 -> 2625 | L12: =+K12/C12 -> 0.46337158 | M12: =+E12-D12 -> 3590 | N12: =+M12/D12 -> 0.43305187
B14: Terrenos | C14: =+'ESTADO DE SITUACION FINANCIERA'!D16 -> 400 | D14: =+'ESTADO DE SITUACION FINANCIERA'!E16 -> 400 | E14: =+'ESTADO DE SITUACION FINANCIERA'!F16 -> 500 | G14: =+C14/$C$19 -> 0.042283298 | H14: =+D14/$D$19 -> 0.032813782 | I14: =+E14/$E$19 -> 0.026752274 | K14: =+D14-C14 -> 0 | L14: 0 | M14: =+E14-D14 -> 100 | N14: =+M14/D14 -> 0.25
B15: Edificios | C15: =+'ESTADO DE SITUACION FINANCIERA'!D17 -> 2295 | D15: =+'ESTADO DE SITUACION FINANCIERA'!E17 -> 2550 | E15: =+'ESTADO DE SITUACION FINANCIERA'!F17 -> 3750 | G15: =+C15/$C$19 -> 0.24260042 | H15: =+D15/$D$19 -> 0.20918786 | I15: =+E15/$E$19 -> 0.20064205 | K15: =+D15-C15 -> 255 | L15: =+K15/C15 -> 0.11111111 | M15: =+E15-D15 -> 1200 | N15: =+M15/D15 -> 0.47058824
B16: Maquinaria y Equipo | C16: =+'ESTADO DE SITUACION FINANCIERA'!D18 -> 1555 | D16: =+'ESTADO DE SITUACION FINANCIERA'!E18 -> 1625 | E16: =+'ESTADO DE SITUACION FINANCIERA'!F18 -> 3605 | G16: =+C16/$C$19 -> 0.16437632 | H16: =+D16/$D$19 -> 0.13330599 | I16: =+E16/$E$19 -> 0.1928839 | K16: =+D16-C16 -> 70 | L16: =+K16/C16 -> 0.045016077 | M16: =+E16-D16 -> 1980 | N16: =+M16/D16 -> 1.2184615
B17: Depreciación Acumulada | C17: =+'ESTADO DE SITUACION FINANCIERA'!D19 -> -455 | D17: =+'ESTADO DE SITUACION FINANCIERA'!E19 -> -675 | E17: =+'ESTADO DE SITUACION FINANCIERA'!F19 -> -1045 | G17: =+C17/$C$19 -> -0.048097252 | H17: =+D17/$D$19 -> -0.055373257 | I17: =+E17/$E$19 -> -0.055912253 | K17: =+D17-C17 -> -220 | L17: =+K17/C17 -> 0.48351648 | M17: =+E17-D17 -> -370 | N17: =+M17/D17 -> 0.54814815
B18: Total Activos Fijos | C18: =SUM(C14:C17) -> 3795 | D18: =SUM(D14:D17) -> 3900 | E18: =SUM(E14:E17) -> 6810 | G18: =+C18/$C$19 -> 0.40116279 | H18: =+D18/$D$19 -> 0.31993437 | I18: =+E18/$E$19 -> 0.36436597 | K18: =+D18-C18 -> 105 | L18: =+K18/C18 -> 0.027667984 | M18: =+E18-D18 -> 2910 | N18: =+M18/D18 -> 0.74615385
B19: TOTAL ACTIVOS | C19: =+C18+C12 -> 9460 | D19: =+D18+D12 -> 12190 | E19: =+E18+E12 -> 18690 | G19: =+C19/$C$19 -> 1 | H19: =+D19/$D$19 -> 1 | I19: =+E19/$E$19 -> 1 | K19: =+D19-C19 -> 2730 | L19: =+K19/C19 -> 0.28858351 | M19: =+E19-D19 -> 6500 | N19: =+M19/D19 -> 0.53322395
B21: PASIVOS
B22: Obligaciones financieras Corto Plazo | C22: ='ESTADO DE SITUACION FINANCIERA'!D24 -> 1476 | D22: ='ESTADO DE SITUACION FINANCIERA'!E24 -> 1668 | E22: ='ESTADO DE SITUACION FINANCIERA'!F24 -> 4711 | G22: =+C22/$C$19 -> 0.15602537 | H22: =+D22/$D$19 -> 0.13683347 | I22: =+E22/$E$19 -> 0.25205993 | K22: =+D22-C22 -> 192 | L22: =+K22/C22 -> 0.1300813 | M22: =+E22-D22 -> 3043 | N22: =+M22/D22 -> 1.8243405
B23: Impuestos por pagar | C23: =+'ESTADO DE SITUACION FINANCIERA'!D25 -> 232.9 | D23: =+'ESTADO DE SITUACION FINANCIERA'!E25 -> 491.8134 | E23: =+'ESTADO DE SITUACION FINANCIERA'!F25 -> 522.1062 | G23: =+C23/$C$19 -> 0.02461945 | H23: =+D23/$D$19 -> 0.040345644 | I23: =+E23/$E$19 -> 0.027935056 | K23: =+D23-C23 -> 258.9134 | L23: =+K23/C23 -> 1.1116934 | M23: =+E23-D23 -> 30.2928 | N23: =+M23/D23 -> 0.061594092
B24: Proveedores | C24: =+'ESTADO DE SITUACION FINANCIERA'!D26 -> 1905 | D24: =+'ESTADO DE SITUACION FINANCIERA'!E26 -> 2205 | E24: =+'ESTADO DE SITUACION FINANCIERA'!F26 -> 4009 | G24: =+C24/$C$19 -> 0.20137421 | H24: =+D24/$D$19 -> 0.18088597 | I24: =+E24/$E$19 -> 0.21449973 | K24: =+D24-C24 -> 300 | L24: =+K24/C24 -> 0.15748031 | M24: =+E24-D24 -> 1804 | N24: =+M24/D24 -> 0.81814059
B25: Total Pasivos Corrientes o a Corto Plazo | C25: =SUM(C22:C24) -> 3613.9 | D25: =SUM(D22:D24) -> 4364.8134 | E25: =SUM(E22:E24) -> 9242.1062 | G25: =+C25/$C$19 -> 0.38201903 | H25: =+D25/$D$19 -> 0.35806509 | I25: =+E25/$E$19 -> 0.49449471 | K25: =+D25-C25 -> 750.9134 | L25: =+K25/C25 -> 0.20778478 | M25: =+E25-D25 -> 4877.2928 | N25: =+M25/D25 -> 1.1174115
B26: Obligaciones financieras largo plazo | C26: =+'ESTADO DE SITUACION FINANCIERA'!D28 -> 350 | D26: =+'ESTADO DE SITUACION FINANCIERA'!E28 -> 1500 | E26: =+'ESTADO DE SITUACION FINANCIERA'!F28 -> 1250 | G26: =+C26/$C$19 -> 0.036997886 | H26: =+D26/$D$19 -> 0.12305168 | I26: =+E26/$E$19 -> 0.066880685 | K26: =+D26-C26 -> 1150 | L26: =+K26/C26 -> 3.2857143 | M26: =+E26-D26 -> -250 | N26: =+M26/D26 -> -0.16666667
B27: TOTAL PASIVO | C27: =C25+C26 -> 3963.9 | D27: =D25+D26 -> 5864.8134 | E27: =E25+E26 -> 10492.106 | G27: =+C27/$C$19 -> 0.41901691 | H27: =+D27/$D$19 -> 0.48111677 | I27: =+E27/$E$19 -> 0.5613754 | K27: =+D27-C27 -> 1900.9134 | L27: =+K27/C27 -> 0.47955635 | M27: =+E27-D27 -> 4627.2928 | N27: =+M27/D27 -> 0.78899233
B29: PATRIMONIO
B30: Capital | C30: =+'ESTADO DE SITUACION FINANCIERA'!D32 -> 4660 | D30: =+'ESTADO DE SITUACION FINANCIERA'!E32 -> 5110 | E30: =+'ESTADO DE SITUACION FINANCIERA'!F32 -> 6110 | G30: =+C30/$C$19 -> 0.49260042 | H30: =+D30/$D$19 -> 0.41919606 | I30: =+E30/$E$19 -> 0.32691279 | K30: =+D30-C30 -> 450 | L30: =+K30/C30 -> 0.096566524 | M30: =+E30-D30 -> 1000 | N30: =+M30/D30 -> 0.19569472
B31: Utilidad del ejercicio | C31: =+'ESTADO DE SITUACION FINANCIERA'!D33 -> 452.1 | D31: =+'ESTADO DE SITUACION FINANCIERA'!E33 -> 954.6966 | E31: =+'ESTADO DE SITUACION FINANCIERA'!F33 -> 1060.0338 | G31: =+C31/$C$19 -> 0.047790698 | H31: =+D31/$D$19 -> 0.078318015 | I31: =+E31/$E$19 -> 0.056716629 | K31: =+D31-C31 -> 502.5966 | L31: =+K31/C31 -> 1.1116934 | M31: =+E31-D31 -> 105.3372 | N31: =+M31/D31 -> 0.11033579
B32: Utilidades retenidas | C32: =+'ESTADO DE SITUACION FINANCIERA'!D34 -> 384 | D32: =+'ESTADO DE SITUACION FINANCIERA'!E34 -> 260 | E32: =+'ESTADO DE SITUACION FINANCIERA'!F34 -> 1028 | G32: =+C32/$C$19 -> 0.040591966 | H32: =+D32/$D$19 -> 0.021328958 | I32: =+E32/$E$19 -> 0.055002675 | K32: =+D32-C32 -> -124 | L32: =+K32/C32 -> -0.32291667 | M32: =+E32-D32 -> 768 | N32: =+M32/D32 -> 2.9538462
B33: Total Patrimonio | C33: =+'ESTADO DE SITUACION FINANCIERA'!D35 -> 5496.1 | D33: =+'ESTADO DE SITUACION FINANCIERA'!E35 -> 6324.6966 | E33: =+'ESTADO DE SITUACION FINANCIERA'!F35 -> 8198.0338 | G33: =+C33/$C$19 -> 0.58098309 | H33: =+D33/$D$19 -> 0.51884304 | I33: =+E33/$E$19 -> 0.43863209 | K33: =+D33-C33 -> 828.5966 | L33: =+K33/C33 -> 0.15076083 | M33: =+E33-D33 -> 1873.3372 | N33: =+M33/D33 -> 0.296194
B34: TOTAL PASIVO Y PATRIMONIO | C34: =C33+C27 -> 9460 | D34: =D33+D27 -> 12189.51 | E34: =E33+E27 -> 18690.14 | G34: =+C34/$C$19 -> 1 | H34: =+D34/$D$19 -> 0.9999598 | I34: =+E34/$E$19 -> 1.0000075 | K34: =+D34-C34 -> 2729.51 | L34: 1 | M34: =+E34-D34 -> 6500.63 | N34: =+M34/D34 -> 0.53329707
C35: =+C34-C19 -> 0 | D35: =+D34-D19 -> -0.49 | E35: =+E34-E19 -> 0.14
B37: DATOS PARA CALCULO DEL C.C.P.P. | C37: 1 | D37: 2 | E37: 3
B38: Pasivo financiero
B39: Patrimonio con costo
B40: ACTIVOS FINANCIADOS CON COSTO FINANCIERO
B42: COSTO DE LA DEUDA: (Ki) o (Kd)
B43: Tasa de la deuda de corto plazo | C43: 0.26 | D43: 0.24 | E43: 0.27
B44: Tasa de la deuda de largo plazo | C44: =+C43+1.5% -> 0.275 | D44: =+D43+1.5% -> 0.255 | E44: =+E43+1.5% -> 0.285
B46: Gastos financieros (deudas a corto plazo) | D46: =+D43*C22 -> 354.24 | E46: =+E43*D22 -> 450.36
B47: Gastos financieros (deudas a largo plazo) | D47: =+D44*C26 -> 89.25 | E47: =+E44*D26 -> 427.5
...

Sheet INDICADORES
B3: Tamaño de las cuentas principales
C4: Año 1 | D4: Año 2 | E4: Año 3
B5: Ventas netas
B6: Activos
B7: Utilidad Neta
B8: Patrimonio
B10: Tamaño de las cuentas de activos
C11: Año 1 | D11: Año 2 | E11: Año 3
B12: Caja, Bancos (Efectivo)
B13: Cuentas por cobrar
B14: Inventarios
B15: Activos fijos
B17: Tamaño de las cuentas de resultados
C18: Año 1 | D18: Año 2 | E18: Año 3
B19: Ventas
B20: Costo de ventas
B21: Gastos de operación
B22: Gastos financieros
B24: Dinámica de las cuentas principales
C25: Año 1 | D25: Año 2 | E25: Año 3
B26: Crecimiento en ventas
B27: Crecimiento en activos
B28: Crecimiento en utilidad Neta
B29: Crecimiento en patrimonio
B31: Dinámica de las cuentas de activos
C32: Año 1 | D32: Año 2 | E32: Año 3
B33: Crecimiento en efectivo
B34: Crecimiento en cuentas por cobrar
B35: Crecimiento en inventarios
B36: Crecimiento en activos fijos
B38: Dinámica de las cuentas de resultados
C39: Año 1 | D39: Año 2 | E39: Año 3
B40: Crecimiento en ventas
B41: Crecimiento en costo de ventas
B42: Crecimiento en gastos de operación
B43: Crecimiento en gastos financieros
B45: Margen sobre ventas
C46: Año 1 | D46: Año 2 | E46: Año 3
B47: Margen bruto
B48: Margen operativo
...
